Workbook

Sheet Tracker
A1: PROJECT TRACKER
A2: CATEGORY | B2: ACTION | C2: STATUS | D2: PRIORITY | E2: HOURS | F2: START | G2: FINISH | H2: DURATION (DAYS) | I2: NOTES AND COMMENTS
A3: US-01 | As a user, I want to be able to see a dynamic UI that is updated after each message I send rather than a conversational back-and-forth with UI components. | E3: =SUM(E4:E6) -> 5 | F3: 46120 | G3: 46120 | H3: =IF(AND(F3<>"",G3<>""),G3-F3+1,"") -> 1 | K3: Total for Week | L3: =SUMIFS(E:E, C:C, "Complete", A:A, "*Task*", G:G, ">=" & DATE(2026,5,10), G:G, "<=" & DATE(2026,5,16)) -> 11
A4: ↳ Task | B4: Remove UI Components from convo output (keep final summary) | C4: Complete | D4: Medium | E4: 1 | F4: 46120 | G4: 46120 | H4: =IF(AND(F4<>"",G4<>""),G4-F4+1,"") -> 1
A5: ↳ Task | B5: Move UI Drawer components into main area of UI | C5: Complete | D5: Medium | E5: 2 | F5: 46120 | G5: 46120 | H5: =IF(AND(F5<>"",G5<>""),G5-F5+1,"") -> 1
A6: ↳ Task | B6: Move current chat (user query, llm final summary) to floating window | C6: Complete | D6: Medium | E6: 2 | F6: 46120 | G6: 46120 | H6: =IF(AND(F6<>"",G6<>""),G6-F6+1,"") -> 1
A7: US-02 | As a user, I need to be able to see live/real-time data being streamed from backend to UI components. | E7: =SUM(E8:E10) -> 14 | F7: 46120 | G7: 46125 | H7: =IF(AND(F7<>"",G7<>""),G7-F7+1,"") -> 6
A8: ↳ Task | B8: Research whether to send live updates like this MCP -> Orchestrator -> UI or MCP -> UI | C8: Complete | D8: High | E8: 1 | F8: 46120 | G8: 46120 | H8: =IF(AND(F8<>"",G8<>""),G8-F8+1,"") -> 1 | I8: MCP -> Orchestrator -> UI
A9: ↳ Task | B9: Implement live stream using websockets | C9: Complete | D9: High | E9: 8 | F9: 46120 | G9: 46121 | H9: =IF(AND(F9<>"",G9<>""),G9-F9+1,"") -> 2
A10: ↳ Task | B10: Test accuracy and performance | C10: Complete | D10: Low | E10: 5 | F10: 46121 | G10: 46125 | H10: =IF(AND(F10<>"",G10<>""),G10-F10+1,"") -> 5
A11: US-03 | As a user, I want to be able to use this system on Desktop, Browser, Tablet, Mobile, Watch, and TV. | E11: =SUM(E12:E14) -> 31 | H11: =IF(AND(F11<>"",G11<>""),G11-F11+1,"")
A12: ↳ Task | B12: Convert React frontend to Flutter | C12: Ready to Start | D12: Low | E12: 21 | H12: =IF(AND(F12<>"",G12<>""),G12-F12+1,"")
A13: ↳ Task | B13: Connect Watch + TV to mobile device related to user (QR code shown on screen, scanned by mobile) | C13: Ready to Start | D13: Low | E13: 8 | H13: =IF(AND(F13<>"",G13<>""),G13-F13+1,"")
A14: ↳ Task | B14: Notification preferences | C14: Ready to Start | D14: Low | E14: 2 | H14: =IF(AND(F14<>"",G14<>""),G14-F14+1,"")
A15: US-04 | As a user, I need to be able to see the audit log of agent actions. | E15: =SUM(E16:E18) -> 6 | F15: 46140 | G15: 46140 | H15: =IF(AND(F15<>"",G15<>""),G15-F15+1,"") -> 1
A16: ↳ Task | B16: Add button and container to bring up audit log. | C16: Complete | D16: High | E16: 1 | F16: 46140 | G16: 46140 | H16: =IF(AND(F16<>"",G16<>""),G16-F16+1,"") -> 1
A17: ↳ Task | B17: Save all agent actions in database. | C17: Complete | D17: High | E17: 2 | F17: 46140 | G17: 46140 | H17: =IF(AND(F17<>"",G17<>""),G17-F17+1,"") -> 1
A18: ↳ Task | B18: Connect frontend to backend to display agent audits. | C18: Complete | D18: High | E18: 3 | F18: 46140 | G18: 46140 | H18: =IF(AND(F18<>"",G18<>""),G18-F18+1,"") -> 1
A19: US-05 | As a user, I need to be able to upload a variety of file types. | E19: =SUM(E20:E23) -> 11 | F19: 46125 | G19: 46129 | H19: =IF(AND(F19<>"",G19<>""),G19-F19+1,"") -> 5
A20: ↳ Task | B20: Add support for "normal" file type uploads (png, jpeg, md, csv, etc) | C20: Complete | D20: Medium | E20: 2 | F20: 46125 | G20: 46125 | H20: =IF(AND(F20<>"",G20<>""),G20-F20+1,"") -> 1
A21: ↳ Task | B21: Test normal file upload | C21: Complete | D21: Medium | E21: 2 | F21: 46125 | G21: 46125 | H21: =IF(AND(F21<>"",G21<>""),G21-F21+1,"") -> 1
A22: ↳ Task | B22: Add support for medical specific file type uploads (dicom, nzi, czi, etc) | C22: Complete | D22: Medium | E22: 2 | F22: 46129 | G22: 46129 | H22: =IF(AND(F22<>"",G22<>""),G22-F22+1,"") -> 1
A23: ↳ Task | B23: Create tools to read these files and return data. | C23: Complete | D23: Medium | E23: 5 | F23: 46129 | G23: 46129 | H23: =IF(AND(F23<>"",G23<>""),G23-F23+1,"") -> 1
A24: US-06 | As a user, I want to be able to provide feedback on the output of components. As a developer, I want the system to take this feedback and auto update tools that continue to produce errors. | E24: =SUM(E25:E27) -> 10 | F24: 46140 | G24: 46143 | H24: =IF(AND(F24<>"",G24<>""),G24-F24+1,"") -> 4
A25: ↳ Task | B25: Add thumbs up/down -> if thumbs down then show modal for feedback. | C25: Complete | D25: Low | E25: 1 | F25: 46140 | G25: 46140 | H25: =IF(AND(F25<>"",G25<>""),G25-F25+1,"") -> 1
A26: ↳ Task | B26: Use the secondary LLM to read feedback and propose changes (every day), possibly create a PR for review. | C26: Complete | D26: Low | E26: 1 | F26: 46140 | G26: 46140 | H26: =IF(AND(F26<>"",G26<>""),G26-F26+1,"") -> 1
A27: ↳ Task | B27: Create tools to read these files and return data. | C27: Complete | D27: Low | E27: 8 | F27: 46140 | G27: 46140 | H27: =IF(AND(F27<>"",G27<>""),G27-F27+1,"") -> 1
A28: US-07 | As a developer, I need mock auth logic to test the system without having to actually log into the system. | E28: =SUM(E29:E29) -> 2 | F28: 46125 | G28: 46129 | H28: =IF(AND(F28<>"",G28<>""),G28-F28+1,"") -> 5
A29: ↳ Task | B29: Reconnect VITE_MOCK_AUTH environment variable back to the system (or fix where its broken). | C29: Complete | D29: Medium | E29: 2 | F29: 46125 | G29: 46129 | H29: =IF(AND(F29<>"",G29<>""),G29-F29+1,"") -> 5
A30: US-08 | As a user, I want tool tips and a getting started tutorial. | E30: =SUM(E31:E34) -> 6 | F30: 46140 | G30: 46140 | H30: =IF(AND(F30<>"",G30<>""),G30-F30+1,"") -> 1
A31: ↳ Task | B31: Write a guide. | C31: Complete | D31: Low | E31: 1 | F31: 46140 | G31: 46140 | H31: =IF(AND(F31<>"",G31<>""),G31-F31+1,"") -> 1
A32: ↳ Task | B32: Add first user tutorial/walkthrough. | C32: Complete | D32: Low | E32: 3 | F32: 46140 | G32: 46140 | H32: =IF(AND(F32<>"",G32<>""),G32-F32+1,"") -> 1
A33: ↳ Task | B33: Warning about not HIPAA compliant. | C33: Complete | D33: Low | E33: 1 | F33: 46140 | G33: 46140 | H33: =IF(AND(F33<>"",G33<>""),G33-F33+1,"") -> 1
A34: ↳ Task | B34: Add it to the navbar as a link. | C34: Complete | D34: Low | E34: 1 | F34: 46140 | G34: 46140 | H34: =IF(AND(F34<>"",G34<>""),G34-F34+1,"") -> 1
A35: US-09 | As a user, I want to use my own LLM subscription. | E35: =SUM(E36:E37) -> 4 | F35: 46140 | G35: 46140 | H35: =IF(AND(F35<>"",G35<>""),G35-F35+1,"") -> 1
A36: ↳ Task | B36: Research if Astral can see the amount of tokens left. | C36: Complete | D36: Low | E36: 1 | F36: 46140 | G36: 46140 | H36: =IF(AND(F36<>"",G36<>""),G36-F36+1,"") -> 1 | I36: Can't see if you are going to run out of tokens :(, but will add token usage to frontend.
A37: ↳ Task | B37: Move LLM .env vars to frontend. | C37: Complete | D37: Low | E37: 3 | F37: 46140 | G37: 46140 | H37: =IF(AND(F37<>"",G37<>""),G37-F37+1,"") -> 1
A38: US-10 | As a user, I want a condensed view of all the sidebar buttons. | E38: =SUM(E39:E39) -> 2 | F38: 46142 | G38: 46142 | H38: =IF(AND(F38<>"",G38<>""),G38-F38+1,"") -> 1
A39: ↳ Task | B39: Add a settings/options/something button that shows all the new buttons (audit, tutorial,etc) | C39: Complete | D39: Medium | E39: 2 | F39: 46142 | G39: 46142 | H39: =IF(AND(F39<>"",G39<>""),G39-F39+1,"") -> 1
A40: US-11 | As a user, I want the new chat button to be on the sidebar above recent chats. | E40: =SUM(E41:E41) -> 1 | F40: 46148 | G40: 46148 | H40: =IF(AND(F40<>"",G40<>""),G40-F40+1,"") -> 1
...

Sheet Summary
A1: TIME & EFFORT SUMMARY DASHBOARD
A3: Total Hours | B3: Tasks Complete | C3: In Progress | D3: Ready to Start | E3: Testing
A4: =SUMIF(Tracker!C3:C185,"<>"&"",Tracker!E3:E185) -> 176 | B4: =COUNTIF(Tracker!C3:C185,"Complete") -> 40 | C4: =COUNTIF(Tracker!C3:C185,"In Progress") -> 2 | D4: =COUNTIF(Tracker!C3:C185,"Ready to Start") -> 24 | E4: =COUNTIF(Tracker!C3:C185,"Testing in Progress") -> 0
A6: Status | B6: Task Count | C6: Total Hours | D6: % of Hours | F6: Priority | G6: Tasks | H6: Hours
A7: Ready to Start | B7: =COUNTIF(Tracker!C:C,A7) -> 24 | C7: =SUMIF(Tracker!C:C,A7,Tracker!E:E) -> 55 | D7: =IFERROR(C7/SUM(C7:C10),0) -> 0.3125 | F7: High | G7: =COUNTIF(Tracker!D:D,F7) -> 15 | H7: =SUMIF(Tracker!D:D,F7,Tracker!E:E) -> 46
A8: In Progress | B8: =COUNTIF(Tracker!C:C,A8) -> 2 | C8: =SUMIF(Tracker!C:C,A8,Tracker!E:E) -> 8 | D8: =IFERROR(C8/SUM(C7:C10),0) -> 0.045454545 | F8: Medium | G8: =COUNTIF(Tracker!D:D,F8) -> 17 | H8: =SUMIF(Tracker!D:D,F8,Tracker!E:E) -> 52
A9: Testing in Progress | B9: =COUNTIF(Tracker!C:C,A9) -> 0 | C9: =SUMIF(Tracker!C:C,A9,Tracker!E:E) -> 0 | D9: =IFERROR(C9/SUM(C7:C10),0) -> 0 | F9: Low | G9: =COUNTIF(Tracker!D:D,F9) -> 34 | H9: =SUMIF(Tracker!D:D,F9,Tracker!E:E) -> 78
A10: Complete | B10: =COUNTIF(Tracker!C:C,A10) -> 40 | C10: =SUMIF(Tracker!C:C,A10,Tracker!E:E) -> 113 | D10: =IFERROR(C10/SUM(C7:C10),0) -> 0.64204545
A11: TOTAL | B11: =SUM(B7:B10) -> 66 | C11: =SUM(C7:C10) -> 176 | D11: =SUM(D7:D10) -> 1
A27: ℹ️ Hours use the Fibonacci scale (1,2,3,5,8,13,21,34,55,89). Duration on the Tracker sheet is auto-calculated: Finish − Start + 1.
